Workbook

Sheet 账户核对
A1: 账户核对：13:00汇总页 vs 14:30明细（as-of=2026-09-08 14:30）
A3: 一、两时点总资产勾稽
A4: 项目 | B4: 13:00汇总页 | C4: 14:30明细 | D4: 差额(13:00-14:30) | E4: 差额来源
A5: 证券市值 | B5: =SUMPRODUCT(参数与费率!$C$4:$C$8,参数与费率!$G$4:$G$8) | C5: =SUMPRODUCT(参数与费率!$C$4:$C$8,参数与费率!$F$4:$F$8) | D5: =B5-C5 | E5: EQ01由26→25、EQ02由31→30，其余价格不变
A6: 现金 | B6: =参数与费率!$B$10 | C6: =参数与费率!$B$10 | D6: =B6-C6 | E6: 现金全天未变(今日买入已在晨间扣过)
A7: 净资产合计 | B7: =B5+B6 | C7: =C5+C6 | D7: =B7-C7 | E7: 汇总页未随14:30报价更新；采用14:30为测算基准
A8: 与汇总页总资产对账 | B8: =参数与费率!$B$11 | C8: =B7 | D8: =B8-C8 | E8: 13:00勾平=0即与交接记录一致；14:30为新基准
A10: 二、批次台账与未调整盈亏（按14:30价）
A11: 代号 | B11: 批次 | C11: 数量 | D11: 批次成本 | E11: 14:30价 | F11: 14:30市值 | G11: 浮动盈亏 | H11: 权重(/净资产) | I11: 今日可卖
A12: =参数与费率!$A$4 | B12: =参数与费率!$B$4 | C12: =参数与费率!$C$4 | D12: =参数与费率!$D$4 | E12: =参数与费率!$F$4 | F12: =C12*E12 | G12: =F12-D12 | H12: =F12/$C$7 | I12: =参数与费率!$E$4
A13: =参数与费率!$A$5 | B13: =参数与费率!$B$5 | C13: =参数与费率!$C$5 | D13: =参数与费率!$D$5 | E13: =参数与费率!$F$5 | F13: =C13*E13 | G13: =F13-D13 | H13: =F13/$C$7 | I13: =参数与费率!$E$5
A14: =参数与费率!$A$6 | B14: =参数与费率!$B$6 | C14: =参数与费率!$C$6 | D14: =参数与费率!$D$6 | E14: =参数与费率!$F$6 | F14: =C14*E14 | G14: =F14-D14 | H14: =F14/$C$7 | I14: =参数与费率!$E$6
A15: =参数与费率!$A$7 | B15: =参数与费率!$B$7 | C15: =参数与费率!$C$7 | D15: =参数与费率!$D$7 | E15: =参数与费率!$F$7 | F15: =C15*E15 | G15: =F15-D15 | H15: =F15/$C$7 | I15: =参数与费率!$E$7
A16: =参数与费率!$A$8 | B16: =参数与费率!$B$8 | C16: =参数与费率!$C$8 | D16: =参数与费率!$D$8 | E16: =参数与费率!$F$8 | F16: =C16*E16 | G16: =F16-D16 | H16: =F16/$C$7 | I16: =参数与费率!$E$8
A17: 证券合计 | C17: =SUM(C12:C16) | D17: =SUM(D12:D16) | F17: =SUM(F12:F16) | G17: =SUM(G12:G16) | H17: =SUM(H12:H16) | I17: =SUM(I12:I16)
A18: 现金(账上) | C18: — | F18: =C6 | G18: =F18-F18 | H18: =F18/C7
A19: 净资产合计 | F19: =F17+F18 | H19: =H17+H18
A20: 三、未调整状态下四项硬约束初判（分母=14:30净资产C7）
A21: 约束 | B21: 阈值 | C21: 当前值 | D21: 判定 | H21: =H19
A22: 单只股票≤25% | B22: =参数与费率!$B$18 | C22: =MAX(F12/C7,F13/C7+F14/C7,F15/C7) | D22: =IF(C22<=B22,"达标","超限")
A23: 新能源(光伏+电池)≤45% | B23: =参数与费率!$B$19 | C23: =(F12+F13+F14)/C7 | D23: =IF(C23<=B23,"达标","超限")
A24: 现金≥300,000 | B24: =参数与费率!$B$20 | C24: =参数与费率!$B$10 | D24: =IF(C24>=B24,"达标","超限")
A25: 联动情景损失≤12% | B25: =参数与费率!$B$21 | C25: =(F12*参数与费率!$B$23+(F13+F14)*参数与费率!$C$23+F15*参数与费率!$D$23+F16*参数与费率!$E$23)/C7 | D25: =IF(C25<=B25,"达标","超限")
A27: 勾稽结论：13:00总资产2,030,000与按13:00价重算一致；14:30因光伏、电池各下跌1元/股，净资产回落至1,990,000，差40,000全部为市价波动，现金未动、今日买入122,000不重复扣。

Sheet 参数与费率
A1: 参数与费率（黄色单元格为输入；其余表全部引用本表，改黄色格即全簿重算）
A3: 代号 | B3: 名称 | C3: 数量 | D3: 批次成本(元) | E3: 今日可卖 | F3: 14:30买一价 | G3: 13:00参考价
A4: EQ01 | B4: 光伏设备 | C4: 20000 | D4: 600000 | E4: 20000 | F4: 25 | G4: 26
A5: EQ02 | B5: 电池制造(旧批) | C5: 16000 | D5: 560000 | E5: 16000 | F5: 30 | G5: 31
A6: EQ02 | B6: 电池制造(今日10:12买入,当日不可卖) | C6: 4000 | D6: 122000 | E6: 0 | F6: 30 | G6: 31
A7: EQ03 | B7: 公用事业 | C7: 30000 | D7: 240000 | E7: 30000 | F7: 10 | G7: 10
A8: ETF01 | B8: A股宽基ETF | C8: 120000 | D8: 336000 | E8: 120000 | F8: 3 | G8: 3
A10: 起始现金(14:30，已扣今日买入电池122,000) | B10: 230000
A11: 13:00汇总页总资产 | B11: 2030000
A12: 批次总成本(全部) | B12: =SUM(D4:D8)
A14: 费率、约束与冲击（输入）
A15: 股票卖出费率 | B15: 0.0008
A16: ETF卖出费率 | B16: 0.0003
A17: 每笔最低费用(元) | B17: 5
A18: 单只股票权重上限 | B18: 0.25
A19: 新能源(光伏+电池)合计上限 | B19: 0.45
A20: 现金下限(元) | B20: 300000
A21: 联动损失率上限 | B21: 0.12
A23: 联动冲击跌幅（光伏/电池/公用事业/宽基ETF） | B23: 0.25 | C23: 0.25 | D23: 0.08 | E23: 0.12
A24: 次日新能源额外下跌 | B24: 0.05
A26: 说明：今日可卖=0的电池批(第6行)不得计入今日卖出；股票/ETF按100股(份)整数倍；9/9开盘前再核可卖数与报价。

Sheet 调整与情景测算
A1: 调整与情景测算：只卖盈利 vs 按风险减仓（14:30价测算；黄色=拟卖数量输入）
A3: 项目 | B3: 未调整(14:30) | C3: A 只卖盈利品种 | D3: B 按风险减仓(建议) | E3: C 坚持全留电池
A4: 拟卖 EQ01 光伏(股) | B4: 0 | C4: 0 | D4: 12500 | E4: 20000
A5: 拟卖 EQ02 电池旧批(股) | B5: 0 | C5: 0 | D5: 3500 | E5: 0
A6: 拟卖 EQ03 公用事业(股) | B6: 0 | C6: 7100 | D6: 0 | E6: 0
A7: 拟卖 ETF01(份) | B7: 0 | C7: 0 | D7: 0 | E7: 0
A8: 卖出成交额(毛) | B8: =B4*参数与费率!$F$4+B5*参数与费率!$F$5+B6*参数与费率!$F$7+B7*参数与费率!$F$8 | C8: =C4*参数与费率!$F$4+C5*参数与费率!$F$5+C6*参数与费率!$F$7+C7*参数与费率!$F$8 | D8: =D4*参数与费率!$F$4+D5*参数与费率!$F$5+D6*参数与费率!$F$7+D7*参数与费率!$F$8 | E8: =E4*参数与费率!$F$4+E5*参数与费率!$F$5+E6*参数与费率!$F$7+E7*参数与费率!$F$8
A9: 卖出费用合计 | B9: =IF(B4=0,0,MAX(B4*参数与费率!$F$4*参数与费率!$B$15,参数与费率!$B$17))+IF(B5=0,0,MAX(B5*参数与费率!$F$5*参数与费率!$B$15,参数与费率!$B$17))+IF(B6=0,0,MAX(B6*参数与费率!$F$7*参数与费率!$B$15,参数与费率!$B$17))+IF(B7=0,0,MAX(B7*参数与费率!$F$8*参数与费率!$B$16,参数与费率!$B$17)) | C9: =IF(C4=0,0,MAX(C4*参数与费率!$F$4*参数与费率!$B$15,参数与费率!$B$17))+IF(C5=0,0,MAX(C5*参数与费率!$F$5*参数与费率!$B$15,参数与费率!$B$17))+IF(C6=0,0,MAX(C6*参数与费率!$F$7*参数与费率!$B$15,参数与费率!$B$17))+IF(C7=0,0,MAX(C7*参数与费率!$F$8*参数与费率!$B$16,参数与费率!$B$17)) | D9: =IF(D4=0,0,MAX(D4*参数与费率!$F$4*参数与费率!$B$15,参数与费率!$B$17))+IF(D5=0,0,MAX(D5*参数与费率!$F$5*参数与费率!$B$15,参数与费率!$B$17))+IF(D6=0,0,MAX(D6*参数与费率!$F$7*参数与费率!$B$15,参数与费率!$B$17))+IF(D7=0,0,MAX(D7*参数与费率!$F$8*参数与费率!$B$16,参数与费率!$B$17)) | E9: =IF(E4=0,0,MAX(E4*参数与费率!$F$4*参数与费率!$B$15,参数与费率!$B$17))+IF(E5=0,0,MAX(E5*参数与费率!$F$5*参数与费率!$B$15,参数与费率!$B$17))+IF(E6=0,0,MAX(E6*参数与费率!$F$7*参数与费率!$B$15,参数与费率!$B$17))+IF(E7=0,0,MAX(E7*参数与费率!$F$8*参数与费率!$B$16,参数与费率!$B$17))
A10: 净回笼现金 | B10: =B8-B9 | C10: =C8-C9 | D10: =D8-D9 | E10: =E8-E9
A11: 成交后现金 | B11: =参数与费率!$B$10+B10 | C11: =参数与费率!$B$10+C10 | D11: =参数与费率!$B$10+D10 | E11: =参数与费率!$B$10+E10
A12: 成交后净资产D(分母) | B12: ='账户核对'!$C$7-B9 | C12: ='账户核对'!$C$7-C9 | D12: ='账户核对'!$C$7-D9 | E12: ='账户核对'!$C$7-E9
A13: EQ01 剩余市值 | B13: =(参数与费率!$C$4-B4)*参数与费率!$F$4 | C13: =(参数与费率!$C$4-C4)*参数与费率!$F$4 | D13: =(参数与费率!$C$4-D4)*参数与费率!$F$4 | E13: =(参数与费率!$C$4-E4)*参数与费率!$F$4
A14: EQ02 剩余市值 | B14: =((参数与费率!$C$5-B5)+参数与费率!$C$6)*参数与费率!$F$5 | C14: =((参数与费率!$C$5-C5)+参数与费率!$C$6)*参数与费率!$F$5 | D14: =((参数与费率!$C$5-D5)+参数与费率!$C$6)*参数与费率!$F$5 | E14: =((参数与费率!$C$5-E5)+参数与费率!$C$6)*参数与费率!$F$5
A15: EQ03 剩余市值 | B15: =(参数与费率!$C$7-B6)*参数与费率!$F$7 | C15: =(参数与费率!$C$7-C6)*参数与费率!$F$7 | D15: =(参数与费率!$C$7-D6)*参数与费率!$F$7 | E15: =(参数与费率!$C$7-E6)*参数与费率!$F$7
A16: ETF 剩余市值 | B16: =(参数与费率!$C$8-B7)*参数与费率!$F$8 | C16: =(参数与费率!$C$8-C7)*参数与费率!$F$8 | D16: =(参数与费率!$C$8-D7)*参数与费率!$F$8 | E16: =(参数与费率!$C$8-E7)*参数与费率!$F$8
A17: 持仓市值合计 | B17: =SUM(B13:B16) | C17: =SUM(C13:C16) | D17: =SUM(D13:D16) | E17: =SUM(E13:E16)
A18: EQ01 权重 | B18: =B13/B12 | C18: =C13/C12 | D18: =D13/D12 | E18: =E13/E12
A19: EQ02 权重 | B19: =B14/B12 | C19: =C14/C12 | D19: =D14/D12 | E19: =E14/E12
A20: EQ03 权重 | B20: =B15/B12 | C20: =C15/C12 | D20: =D15/D12 | E20: =E15/E12
A21: ETF 权重 | B21: =B16/B12 | C21: =C16/C12 | D21: =D16/D12 | E21: =E16/E12
A22: 现金权重 | B22: =B11/B12 | C22: =C11/C12 | D22: =D11/D12 | E22: =E11/E12
A23: 新能源(光伏+电池)权重 | B23: =(B13+B14)/B12 | C23: =(C13+C14)/C12 | D23: =(D13+D14)/D12 | E23: =(E13+E14)/E12
A24: 联动情景损失额 | B24: =B13*参数与费率!$B$23+B14*参数与费率!$C$23+B15*参数与费率!$D$23+B16*参数与费率!$E$23 | C24: =C13*参数与费率!$B$23+C14*参数与费率!$C$23+C15*参数与费率!$D$23+C16*参数与费率!$E$23 | D24: =D13*参数与费率!$B$23+D14*参数与费率!$C$23+D15*参数与费率!$D$23+D16*参数与费率!$E$23 | E24: =E13*参数与费率!$B$23+E14*参数与费率!$C$23+E15*参数与费率!$D$23+E16*参数与费率!$E$23
A25: 联动损失率 | B25: =B24/B12 | C25: =C24/C12 | D25: =D24/D12 | E25: =E24/E12
A26: 单股 EQ01≤25% | B26: =IF(B18<=参数与费率!$B$18,"达标","超限") | C26: =IF(C18<=参数与费率!$B$18,"达标","超限") | D26: =IF(D18<=参数与费率!$B$18,"达标","超限") | E26: =IF(E18<=参数与费率!$B$18,"达标","超限")
A27: 单股 EQ02≤25% | B27: =IF(B19<=参数与费率!$B$18,"达标","超限") | C27: =IF(C19<=参数与费率!$B$18,"达标","超限") | D27: =IF(D19<=参数与费率!$B$18,"达标","超限") | E27: =IF(E19<=参数与费率!$B$18,"达标","超限")
A28: 新能源≤45% | B28: =IF(B23<=参数与费率!$B$19,"达标","超限") | C28: =IF(C23<=参数与费率!$B$19,"达标","超限") | D28: =IF(D23<=参数与费率!$B$19,"达标","超限") | E28: =IF(E23<=参数与费率!$B$19,"达标","超限")
A29: 现金≥30万 | B29: =IF(B11>=参数与费率!$B$20,"达标","超限") | C29: =IF(C11>=参数与费率!$B$20,"达标","超限") | D29: =IF(D11>=参数与费率!$B$20,"达标","超限") | E29: =IF(E11>=参数与费率!$B$20,"达标","超限")
A30: 联动损失≤12% | B30: =IF(B25<=参数与费率!$B$21,"达标","超限") | C30: =IF(C25<=参数与费率!$B$21,"达标","超限") | D30: =IF(D25<=参数与费率!$B$21,"达标","超限") | E30: =IF(E25<=参数与费率!$B$21,"达标","超限")
A31: 四项同时达标? | B31: =IF(AND(B26="达标",B27="达标",B28="达标",B29="达标",B30="达标"),"四项同时达标","未达标") | C31: =IF(AND(C26="达标",C27="达标",C28="达标",C29="达标",C30="达标"),"四项同时达标","未达标") | D31: =IF(AND(D26="达标",D27="达标",D28="达标",D29="达标",D30="达标"),"四项同时达标","未达标") | E31: =IF(AND(E26="达标",E27="达标",E28="达标",E29="达标",E30="达标"),"四项同时达标","未达标")
A33: 二、B方案（建议）逐笔成交与实现盈亏（扣费后口径）
A34: 标的 | B34: 卖出数量 | C34: 14:30价 | D34: 成交额 | E34: 费率 | F34: 费用 | G34: 净回笼 | H34: 单位成本 | I34: 实现盈亏(扣费后)
A35: EQ01 光伏 | B35: =D4 | C35: =参数与费率!$F$4 | D35: =B35*C35 | E35: =参数与费率!$B$15 | F35: =IF(B35=0,0,MAX(D35*E35,参数与费率!$B$17)) | G35: =D35-F35 | H35: =参数与费率!$D$4/参数与费率!$C$4 | I35: =B35*(C35-H35)-F35
A36: EQ02 电池旧批 | B36: =D5 | C36: =参数与费率!$F$5 | D36: =B36*C36 | E36: =参数与费率!$B$15 | F36: =IF(B36=0,0,MAX(D36*E36,参数与费率!$B$17)) | G36: =D36-F36 | H36: =参数与费率!$D$5/参数与费率!$C$5 | I36: =B36*(C36-H36)-F36
A37: EQ03 公用事业 | B37: =D6 | C37: =参数与费率!$F$7 | D37: =B37*C37 | E37: =参数与费率!$B$15 | F37: =IF(B37=0,0,MAX(D37*E37,参数与费率!$B$17)) | G37: =D37-F37 | H37: =参数与费率!$D$7/参数与费率!$C$7 | I37: =B37*(C37-H37)-F37
A38: ETF01 宽基 | B38: =D7 | C38: =参数与费率!$F$8 | D38: =B38*C38 | E38: =参数与费率!$B$16 | F38: =IF(B38=0,0,MAX(D38*E38,参数与费率!$B$17)) | G38: =D38-F38 | H38: =参数与费率!$D$8/参数与费率!$C$8 | I38: =B38*(C38-H38)-F38
A39: 合计 | D39: =SUM(D35:D38) | F39: =SUM(F35:F38) | G39: =SUM(G35:G38) | I39: =SUM(I35:I38)
A41: 三、次日(9/9)情景：以B方案成交后持仓为起点，新能源先再跌5%，再加相同联动冲击
A42: 项目 | B42: 数值 | C42: 说明
A43: B成交后现金 | B43: =D11 | C43: 今日已扣费用不再扣
...

Sheet 客户沟通说明
A1: 客户沟通说明（可直接使用；9/8收盘前电话/微信口径）
A2: 【结论】今天建议按组合风险减仓，而不是只卖赚钱的公用事业。只卖公用事业只能把现金补到30万，单股、新能源集中度和12%联动损失三项仍不达标；按风险减仓后四项约束可同时满足。
A4: 一、为什么不能只卖赚钱的公用事业、把亏损电池留着
A5: · 账户14:30净资产1,990,000元。其中光伏500,000(25.1%)、电池600,000(30.2%)、公用事业300,000(15.1%)、宽基ETF360,000(18.1%)，现金230,000。
A6: · 光伏+电池合计1,100,000，占55.3%，已超45%上限；电池单票30.2%、光伏25.1%，均超单票25%；现金23万低于30万；联动情景(光伏电池同跌25%、公用跌8%、ETF跌12%)损失342,200，占17.2%，超12%预算。
A7: · 只卖公用事业(卖7,100股)后，现金补到约30.1万达标，但光伏、电池市值一分没减，权重反而因分母变小略升：新能源仍55.3%、电池30.2%、联动损失率16.9%——四项里只过了现金一项。卖盈利品种救不了集中度，因为超配的恰恰是亏损的光伏和电池。
A9: 二、建议方案(按组合风险减仓)
A10: · 卖出：光伏EQ01 12,500股(约31.25万)、电池旧批EQ02 3,500股(约10.5万)；公用事业和宽基ETF保留不动。
A11: · 成交后：现金约64.7万，光伏降到约9.4%、电池保留16,500股(约24.9%)、新能源约34.3%、联动损失约237,825、占11.95%。四项约束同时达标。
A12: · 费用合计约334元(股票成交额0.08%、每笔最低5元)。实现亏损约80,334元(光伏每卖一股亏5元、电池旧批每股亏5元)——这是把账面亏损转为实际亏损，目的是把集中度和尾部损失压回预算内，不是看空后不再持有。
A13: · 今天10:12新买的4,000股电池当日不可卖，不纳入今天任何卖量；这部分与旧批一并保留。
A15: 三、如果坚持一股电池都不卖
... A26: · 以上为基于9/8 14:30买一价的条件测算，不连接券商、不代下单、不承诺回本；实际以收盘前报价、可卖数与风控确认为准。

Sheet 核验
A1: 核验表：抽查关键单元格公式与独立重算值是否一致
A2: 被核验指标 | B2: 取值所在单元格 | C2: 该单元格公式原文 | D2: 独立重算值(Python) | E2: 与正文是否一致
A3: 14:30净资产(勾稽) | B3: 账户核对!C7 | C3: 证券市值+现金=1,760,000+230,000 | D3: 1,990,000 | E3: 一致
A4: 13:00与14:30差额 | B4: 账户核对!D7 | C4: 2,030,000-1,990,000 | D4: 40,000(光伏-2万+电池-2万) | E4: 一致
A5: B方案费用合计 | B5: 调整与情景测算!D9 | C5: MAX(12500*25*.0008,5)+MAX(3500*30*.0008,5) | D5: 334.00 | E5: 一致
A6: B方案成交后现金 | B6: 调整与情景测算!D11 | C6: 230000+417500-334 | D6: 647,166.00 | E6: 一致
A7: B方案净资产D | B7: 调整与情景测算!D12 | C7: 1,990,000-334 | D7: 1,989,666.00 | E7: 一致
A8: B方案EQ02权重 | B8: 调整与情景测算!D19 | C8: 495000/1,989,666 | D8: 24.88% | E8: 一致
A9: B方案新能源权重 | B9: 调整与情景测算!D23 | C9: 682500/1,989,666 | D9: 34.30% | E9: 一致
A10: B方案联动损失率 | B10: 调整与情景测算!D25 | C10: 237825/1,989,666 | D10: 11.95% | E10: 一致
A11: A方案现金 | B11: 调整与情景测算!C11 | C11: 230000+71000-56.8 | D11: 300,943.20 | E11: 一致
A12: A方案联动损失率 | B12: 调整与情景测算!C25 | C12: 336520/1,989,943.2 | D12: 16.91% | E12: 一致
A13: 次日-5%后新分母 | B13: 调整与情景测算!B | C13: 持仓1,308,375+现金647,166 | D13: 1,955,541 | E13: 一致
... A15: 权重加总(含现金) | B15: 账户核对!H19 | C15: 五证券权重+现金权重 | D15: 100.00% | E15: 一致

Sheet 自检与假设
A1: 交付自检回执 + 假设与缺失清单
A2: 一、自检回执表（逐行填值）
A3: 交付清单(只列文件名) | B3: 集中持仓复核与处理方案_20260908.xlsx
A4: 交付主工件位置 | B4: 本工作簿「调整与情景测算」表第三~五节 + 「客户沟通说明」表
A5: 工作簿核验表 | B5: 「核验」表(本表外另一张)
A6: 占比分母定义与数值 | B6: 所有权重/损失率分母=扣除本方案费用后的净资产D；B方案D=1,989,666
A7: 最紧约束 | B7: 联动情景损失12% / 当前未调整17.20% / B方案反解=卖EQ01 12,500+EQ02旧批3,500 / R1
A8: 分解型占比加总 | B8: B方案五项权重合计=100.00%(已加总核验)
A9: 最不利情景 | B9: 未调整17.20%；A方案16.91%；均>12%不达标；B方案11.95%、次日-5%后11.73%
A10: 日期来源 | B10: 9/8周二、9/9周三均交易日；动作行日期取自材料，无编造
A11: 数量口径 | B11: R1为累计总卖量(基准：EQ01=20,000、EQ02旧批=16,000)；今日买批4,000股不可卖
A12: 费用口径 | B12: 股票0.08%、ETF0.03%、每笔最低5元；B方案费用334，隐含费率=334/417500=0.0799%，与费率表一致
A13: 跨文件一致 | B13: 净资产1,990,000、B现金647,166、损失率11.95%在账户核对/调整/核验三处同值
A16: 二、假设与缺失清单
A17: 条目 | B17: 类型 | C17: 来源/依据 | D17: 影响结论 | E17: 补齐后重算
A18: 14:30买一价为测算价 | B18: 已确认事实 | C18: 材料B5/B13 | D18: 成交价可能偏离 | E18: 成交前按实际买一价重算D与损失率
A19: 今日买入电池4,000股当日不可卖 | B19: 已确认事实 | C19: 材料B11 | D19: 今日卖量不含该批 | E19: 9/9起该批可纳入卖量
A20: 无实时盘口/涨跌停 | B20: 仍缺证据 | C20: 无行情接口 | D20: 成交与否未知 | E20: R2/R3给出未成交与跌停后手
A21: 无负债融资质押 | B21: 已确认事实 | C21: 材料B5 | D21: 净资产=现金+市值 | E21: —
A22: 各品种合并一笔费用 | B22: 合理推断 | C22: 材料B10 | D22: 最低5元已逐笔计 | E22: —
A23: 次日-5%后再联动冲击 | B23: 题设 | C23: 用户本轮定义 | D23: 损失率11.73% | E23: 若实际跌幅不同按新价重算
A24: 未调整方案不计假设费用 | B24: 题设 | C24: 用户本轮定义 | D24: 未调整列D=1,990,000 | E24: —
