Workbook

Sheet 输入快照
A1: 集中持仓复核 — 输入快照（黄色单元格为可改输入；其余工作表公式引用本表）
A3: 账户与费率参数
A4: 复核时点 | B4: 2026-09-08 14:30（周二，交易日）
A5: 13:00汇总页总资产 | B5: 2030000
A6: 13:00现金 | B6: 230000
A7: 14:30现金（未变） | B7: 230000
A8: 调整后现金下限 | B8: 300000
A9: 单只股票权重上限 | B9: 0.25
A10: 新能源(光伏+电池)合计上限 | B10: 0.45
A11: 联动情景损失率上限 | B11: 0.12
A12: 股票卖出综合费率 | B12: 0.0008
A13: ETF卖出综合费率 | B13: 0.0003
A14: 每笔最低佣金(元) | B14: 5
A16: 持仓批次（数量与成本来自附件；14:30买一价为测算基准价）
A17: 代号 | B17: 资产 | C17: 总数量(股/份) | D17: 批次总成本(元) | E17: 今日可卖(股/份) | F17: 13:00价 | G17: 14:30买一价 | H17: 成本单价(元)
A18: EQ01 | B18: 光伏设备 | C18: 20000 | D18: 600000 | E18: 20000 | F18: 26 | G18: 25 | H18: =D18/C18
A19: EQ02 | B19: 电池制造·老批次(今日可卖) | C19: 16000 | D19: 560000 | E19: 16000 | F19: 31 | G19: 30 | H19: =D19/C19
A20: EQ02 | B20: 电池制造·今日新批次(今日不可卖) | C20: 4000 | D20: 122000 | E20: 0 | F20: 31 | G20: 30 | H20: =D20/C20
A21: EQ03 | B21: 公用事业 | C21: 30000 | D21: 240000 | E21: 30000 | F21: 10 | G21: 10 | H21: =D21/C21
A22: ETF01 | B22: A股宽基ETF | C22: 120000 | D22: 336000 | E22: 120000 | F22: 3 | G22: 3 | H22: =D22/C22
A24: 联动情景跌幅（附件口径，现金不受冲击）
A25: 光伏/电池同时下跌 | B25: 0.25
A26: 公用事业下跌 | B26: 0.08
A27: 宽基ETF下跌 | B27: 0.12
A29: 说明：今日(9/8)10:12买入的电池新批次4,000股当日不可卖，下一交易日(9/9)起可卖；各品种按100股/100份整数倍卖出。

Sheet 账户核对
A1: 账户核对：13:00 汇总页 vs 14:30 买一价
A3: 一、两套口径勾稽
A4: 项目 | B4: 13:00汇总页 | C4: 14:30买一价 | D4: 差额(14:30-13:00) | E4: 来源
A5: 证券市值合计 | B5: =SUMPRODUCT(输入快照!C18:C22,输入快照!F18:F22) | C5: =SUMPRODUCT(输入快照!C18:C22,输入快照!G18:G22) | D5: =C5-B5 | E5: 13:00按13:00参考价；14:30按买一价
A6: 现金 | B6: =输入快照!$B$6 | C6: =输入快照!$B$7 | D6: =C6-B6 | E6: 现金两时点均为230,000，未变
A7: 账户净资产合计 | B7: =B5+B6 | C7: =C5+C6 | D7: =C7-B7 | E7: 汇总页总资产2,030,000；14:30未随报价更新
A9: 二、差额分解（证券市值为何降40,000）
A10: 品种 | B10: 13:00价 | C10: 14:30价 | D10: 数量 | E10: 价格变动额 | F10: 市值变动(元)
A11: EQ01 光伏设备 | B11: =输入快照!F18 | C11: =输入快照!G18 | D11: =输入快照!C18 | E11: =C11-B11 | F11: =E11*D11
A12: EQ02 电池制造(合计20000股) | B12: =输入快照!F19 | C12: =输入快照!G19 | D12: =输入快照!C19+输入快照!C20 | E12: =C12-B12 | F12: =E12*D12
A13: EQ03 公用事业 / ETF01 宽基 | B13: 价未变 | C13: — | D13: 0 | E13: 0 | F13: 0
A14: 差额合计 | F14: =F11+F12+F13
A16: 结论：14:30净资产1,990,000 = 13:00汇总2,030,000 − 40,000；其中光伏价26→25贡献-20,000，电池价31→30(20,000股)贡献-20,000。现金两时点一致。本次全部测算采用14:30口径(净资产1,990,000)。
A19: 三、14:30各品种市值、浮盈亏与权重
A20: 品种 | B20: 数量 | C20: 14:30价 | D20: 市值(元) | E20: 批次成本(元) | F20: 浮盈亏(元) | G20: 权重(占净资产)
A21: EQ01 光伏设备 | B21: =输入快照!C18 | C21: =输入快照!G18 | D21: =B21*C21 | E21: =输入快照!D18 | F21: =D21-E21 | G21: =D21/$C$7
A22: EQ02 电池·老批次 | B22: =输入快照!C19 | C22: =输入快照!G19 | D22: =B22*C22 | E22: =输入快照!D19 | F22: =D22-E22 | G22: =D22/$C$7
A23: EQ02 电池·今日新批次 | B23: =输入快照!C20 | C23: =输入快照!G20 | D23: =B23*C23 | E23: =输入快照!D20 | F23: =D23-E23 | G23: =D23/$C$7
A24: EQ03 公用事业 | B24: =输入快照!C21 | C24: =输入快照!G21 | D24: =B24*C24 | E24: =输入快照!D21 | F24: =D24-E24 | G24: =D24/$C$7
A25: ETF01 宽基ETF | B25: =输入快照!C22 | C25: =输入快照!G22 | D25: =B25*C25 | E25: =输入快照!D22 | F25: =D25-E25 | G25: =D25/$C$7
A26: 现金 | D26: =输入快照!B7 | G26: =D26/$C$7
A27: 合计校验 | D27: =SUM(D21:D26) | G27: =SUM(G21:G26)

Sheet 调整与情景测算
A1: 调整与情景测算（黄色为可改拟卖数量；成交前须复核实时价、可卖数与涨跌停）
A3: 一、拟卖数量输入（100股/份整数倍；今日新批次电池4,000股不可卖）
A4: 品种 | B4: 14:30价 | C4: 可卖数量 | D4: 方案A:只卖盈利(拟卖) | E4: 方案B:按风险减仓(拟卖) | F4: 成本单价 | G4: 备注
A5: EQ01 光伏设备 | B5: =输入快照!G18 | C5: =输入快照!E18 | D5: 0 | E5: 12000 | F5: =输入快照!H18 | G5: 成本30元/股
A6: EQ02 电池·老批次 | B6: =输入快照!G19 | C6: =输入快照!E19 | D6: 0 | E6: 3800 | F6: =输入快照!H19 | G6: 成本35元/股
A7: EQ02 电池·新批次(锁定) | B7: =输入快照!G20 | C7: =输入快照!E20 | D7: 0 | E7: 0 | F7: =输入快照!H20 | G7: 今日不可卖，留至9/9
A8: EQ03 公用事业 | B8: =输入快照!G21 | C8: =输入快照!E21 | D8: 30000 | E8: 0 | F8: =输入快照!H21 | G8: 成本8元/股
A9: ETF01 宽基ETF | B9: =输入快照!G22 | C9: =输入快照!E22 | D9: 120000 | E9: 0 | F9: =输入快照!H22 | G9: 成本2.8元/份
A11: 二、成交明细与费用（每品种每日合并一笔；股票0.08%/ETF0.03%，最低5元；卖0股不收）
A12: 品种 | B12: 方向 | C12: 方案A成交额 | D12: 方案A费用 | E12: 方案B成交额 | F12: 方案B费用 | G12: 方案A实现盈亏(扣费后) | H12: 方案B实现盈亏(扣费后)
A13: =A5 | B13: 卖出 | C13: =D5*B5 | D13: =IF(C13<=0,0,MAX(输入快照!$B$14,C13*输入快照!$B$12)) | E13: =E5*B5 | F13: =IF(E13<=0,0,MAX(输入快照!$B$14,E13*输入快照!$B$12)) | G13: =D5*(B5-F5)-D13 | H13: =E5*(B5-F5)-F13
A14: =A6 | B14: 卖出 | C14: =D6*B6 | D14: =IF(C14<=0,0,MAX(输入快照!$B$14,C14*输入快照!$B$12)) | E14: =E6*B6 | F14: =IF(E14<=0,0,MAX(输入快照!$B$14,E14*输入快照!$B$12)) | G14: =D6*(B6-F6)-D14 | H14: =E6*(B6-F6)-F14
A15: =A7 | B15: 卖出 | C15: =D7*B7 | D15: =IF(C15<=0,0,MAX(输入快照!$B$14,C15*输入快照!$B$12)) | E15: =E7*B7 | F15: =IF(E15<=0,0,MAX(输入快照!$B$14,E15*输入快照!$B$12)) | G15: =D7*(B7-F7)-D15 | H15: =E7*(B7-F7)-F15
A16: =A8 | B16: 卖出 | C16: =D8*B8 | D16: =IF(C16<=0,0,MAX(输入快照!$B$14,C16*输入快照!$B$12)) | E16: =E8*B8 | F16: =IF(E16<=0,0,MAX(输入快照!$B$14,E16*输入快照!$B$12)) | G16: =D8*(B8-F8)-D16 | H16: =E8*(B8-F8)-F16
A17: =A9 | B17: 卖出 | C17: =D9*B9 | D17: =IF(C17<=0,0,MAX(输入快照!$B$14,C17*输入快照!$B$13)) | E17: =E9*B9 | F17: =IF(E17<=0,0,MAX(输入快照!$B$14,E17*输入快照!$B$13)) | G17: =D9*(B9-F9)-D17 | H17: =E9*(B9-F9)-F17
A18: 合计 | C18: =SUM(C13:C17) | D18: =SUM(D13:D17) | E18: =SUM(E13:E17) | F18: =SUM(F13:F17) | G18: =SUM(G13:G17) | H18: =SUM(H13:H17)
A20: 三、交易后持仓、现金与净资产（分母=扣费用后净资产）
A21: 项目 | B21: 未调整(14:30) | C21: 方案A 只卖盈利 | D21: 方案B 按风险减仓 | E21: 口径
A22: 光伏设备市值 | B22: =输入快照!C18*输入快照!G18 | C22: =(输入快照!C18-D5)*输入快照!G18 | D22: =(输入快照!C18-E5)*输入快照!G18
A23: 电池制造市值(合计) | B23: =(输入快照!C19+输入快照!C20)*输入快照!G19 | C23: =((输入快照!C19-D6)+输入快照!C20)*输入快照!G19 | D23: =((输入快照!C19-E6)+输入快照!C20)*输入快照!G19
A24: 公用事业市值 | B24: =输入快照!C21*输入快照!G21 | C24: =(输入快照!C21-D8)*输入快照!G21 | D24: =(输入快照!C21-E8)*输入快照!G21
A25: 宽基ETF市值 | B25: =输入快照!C22*输入快照!G22 | C25: =(输入快照!C22-D9)*输入快照!G22 | D25: =(输入快照!C22-E9)*输入快照!G22
A26: 现金 | B26: =输入快照!B7 | C26: =输入快照!B7+C18-D18 | D26: =输入快照!B7+E18-F18
A27: 净资产(扣费用后) | B27: =SUM(B22:B25)+B26 | C27: =SUM(C22:C25)+C26 | D27: =SUM(D22:D25)+D26
A28: 权重：光伏 | B28: =B22/B27 | C28: =C22/C27 | D28: =D22/D27
A29: 权重：电池 | B29: =B23/B27 | C29: =C23/C27 | D29: =D23/D27
A30: 权重：新能源合计 | B30: =(B22+B23)/B27 | C30: =(C22+C23)/C27 | D30: =(D22+D23)/D27
A31: 权重：公用事业 | B31: =B24/B27 | C31: =C24/C27 | D31: =D24/D27
A32: 权重：现金 | B32: =B26/B27 | C32: =C26/C27 | D32: =D26/D27
A34: 四、四项硬约束状态（分母=该方案扣费用后净资产）
A35: 约束 | B35: 阈值 | C35: 未调整 | D35: 方案A | E35: 方案B | F35: 判定(方案B) | G35: 说明
A36: 现金≥下限 | B36: =输入快照!$B$8 | C36: =B26 | D36: =C26 | E36: =D26 | F36: =IF(E36>=B36,"达标","超限") | G36: 方案B交易后现金643,669元
A37: 单只股票≤25% | B37: =输入快照!$B$9 | C37: =B29 | D37: =C29 | E37: =D29 | F37: =IF(MAX(D29/D27,D28/D27)<=B37,"达标","超限") | G37: 看最大单票；方案B电池24.43%为最紧
A38: 新能源≤45% | B38: =输入快照!$B$10 | C38: =B30 | D38: =C30 | E38: =D30 | F38: =IF(E38<=B38,"达标","超限") | G38: 光伏+电池合计
A39: 联动损失率≤12% | B39: =输入快照!$B$11 | C39: =((B22+B23)*输入快照!$B$25+B24*输入快照!$B$26+B25*输入快照!$B$27)/B27 | D39: =((C22+C23)*输入快照!$B$25+C24*输入快照!$B$26+C25*输入快照!$B$27)/C27 | E39: =((D22+D23)*输入快照!$B$25+D24*输入快照!$B$26+D25*输入快照!$B$27)/D27 | F39: =IF(E39<=B39,"达标","超限") | G39: 现金不受冲击；费用已扣现金一次不重复计
A41: 五、联动与次日情景（最不利取12%上限）
A42: 情景 | B42: 起点净资产 | C42: 冲击/跌价过程 | D42: 损失额 | E42: 损失率 | F42: 判定
A43: 未调整：联动冲击 | B43: =B27 | C43: NE-25%,公用-8%,ETF-12% | D43: =C39*B27 | E43: =C39 | F43: =IF(E43<=输入快照!$B$11,"达标","超限")
A44: 方案A：联动冲击 | B44: =C27 | C44: NE-25%(已无公用/ETF) | D44: =D39*C27 | E44: =D39 | F44: =IF(E44<=输入快照!$B$11,"达标","超限")
A45: 方案B：联动冲击 | B45: =D27 | C45: NE-25%,公用-8%,ETF-12% | D45: =E39*D27 | E45: =E39 | F45: =IF(E45<=输入快照!$B$11,"达标","超限")
...

Sheet 交易日历与规则
A1: 交易日历与 if→then 交易纪律
A3: 日历日 | B3: 星期 | C3: 是否交易日 | D3: 可执行时段/资金说明 | E3: 备注
A4: 2026-09-08 | B4: 周二 | C4: 是 | D4: 14:30后收盘沟通；今日可卖=除今日新购电池外全部持仓 | E4: 新购电池4,000股T+1不可卖
A5: 2026-09-09 | B5: 周三 | C5: 是 | D5: 开盘前复核可卖数量与价格；新购电池解锁可卖 | E5: 下一交易日
A7: if→then 规则（条件计划，非委托承诺；成交前以实时报价、可卖数、涨跌停为准）
A8: 规则号 | B8: 触发条件(可观察+时点) | C8: 动作 | D8: 数量口径 | E8: 费用/净回笼(14:30基准) | F8: 未成交后手/复核
A9: R1 | B9: 9/8 14:30后，报价与可卖数正常、无涨跌停 | C9: 按方案B挂限价单卖出光伏12,000股+电池老批次3,800股 | D9: 本阶段追加量，基准为当前持仓；累计卖光伏12,000、电池老3,800 | E9: 成交额414,000；费用约331元；净回笼约413,669 | F9: 收盘后复核：电池≤25%、新能源≤45%、联动≤12%、现金≥30万
A10: R2 | B10: 若光伏或电池封跌停/无买盘，方案B无法成交 | C10: 当日不强行成交，按跌停价挂单仅作排队 | D10: 卖量=0 | E10: 费用0、现金不变 | F10: 9/9开盘重挂；当日未达标不属已合规，禁止加仓/做T
A11: R3 | B11: 若部分成交 | C11: 仅按实际成交股数复核四项约束；未成交部分转9/9 | D11: 按实际成交 | E11: 按实际成交额扣费 | F11: 次日开盘补挂至目标量；新购电池4,000股9/9才可卖
A12: R4 | B12: 9/9开盘：新能源(光伏+电池)较今日再跌5% | C12: 以今日方案B收盘后持仓为新起点，不追加交易先复核 | D12: 不交易 | E12: 费用0 | F12: 跌后联动损失率约11.77%仍≤12%；若盘中突破12%则触发减新能源
A13: R5 | B13: 9/9盘中：联动损失率测算>12% 或 电池权重回升>25% | C13: 追加卖出新能源(优先光伏)至回到限内 | D13: 追加量=按当时价反解至目标权重的100股整数倍 | E13: 按新成交额扣费率；先扣费用再以联动前净资产为分母复核 | F13: 卖出后重算四项约束；超限期间不得买入任何证券
A14: R6 | B14: 客户坚持今日不卖任何电池 | C14: 维持现金与新能源约束须另议；本组合无法同时满足单票25% | D14: 电池卖量=0 | E14: — | F14: 须放松单票上限至≥30.2%或增资约41万元；否则须卖≥3,500股电池

Sheet 客户沟通说明
A1: 致客户沟通说明（可直接使用）
A3: 主题 | B3: 关于今日集中持仓复核与减仓安排
A4: 一、账户现状 | B4: 截至9月8日14:30，账户净资产约199.0万元，现金23.0万元。13:00汇总页显示总资产203.0万元，与14:30相差4.0万元，全部来自光伏与电池在过去一个多小时各下跌1元，现金未变。账面整体浮亏约9.8万元，其中光伏亏10.0万、电池亏8.2万；公用事业与宽基ETF分别浮盈6.0万与2.4万。
A5: 二、为什么不能只卖赚钱的品种 | B5: 按您的设想，只把盈利的公用事业和宽基ETF卖出、把亏损的电池股留下：卖出后现金升至约88.9万元，现金一项达标，但风险指标反而变差——新能源(光伏+电池)占比仍高达55.3%，电池单票占30.2%，联动情景损失率升至13.8%，超过12%的风控线。原因是卖掉的正是低波动的公用事业和宽基，留下的全是高波动、同涨同跌的新能源，集中度不降反升。把账面亏损大小当作减仓顺序，会与分散风险的目标相反。
A6: 三、建议的处理方案 | B6: 按组合风险减仓：今日卖出光伏12,000股、电池老批次3,800股(约成交41.4万元)，保留公用事业与宽基ETF。完成后：现金约64.4万元(高于30万元要求)，电池占比24.4%、光伏10.1%，新能源合计34.5%，联动情景损失率约12.0%，四项约束同时达标。该方案会实现约7.9万元亏损，但这是把组合从‘四只约束全部超限’拉回风控线内的必要调整，不代表看空新能源长期逻辑。今日新买入的4,000股电池按规则当日不可卖，未计入今日卖量。
A7: 四、若您坚持保留全部电池股 | B7: 可以理解您不愿割肉电池的想法。但要如实说明：在不追加资金、不加杠杆的前提下，只要电池股维持60万元市值，其占净资产比重就在30%以上，无论怎么卖光伏和其他品种都无法压到25%的单票上限——除非把单票上限放宽到约30%，或额外注入约41万元资金来稀释比重。我们不会替您默认提高风险预算；是否放宽这一条，请您书面确认后我们再执行。
A8: 五、保留的敞口与重新评估触发条件 | B8: 新能源方向仍保留约68.6万元(光伏20万+电池48.6万)，与您‘保留一年’的意愿一致。后续出现以下任一情况我们会主动复核并与您沟通：①联动情景损失率测算重新超过12%；②电池单票占比回升超过25%；③新能源合计超过45%。若9月9日新能源再下跌5%，按本方案持仓测算联动损失率约11.8%，仍在安全线内，但我们会在开盘后第一时间按最新价格重算并向您报备。
A9: 六、执行说明与边界 | B9: 以上均为基于14:30买一价的条件测算，不是委托单；实际成交前会复核实时报价、可卖数量与涨跌停。若跌停或未成交，当日不强行成交，顺延至9月9日按相同纪律处理。本账户不新增证券、不代下单、不承诺回本；所有动作以您确认后另行为准。

Sheet 假设与缺失
A1: 假设与缺失清单
A3: 条目 | B3: 类型 | C3: 依据/影响 | D3: 补齐后需重算
A4: as-of=2026-09-08 14:30 | B4: 已确认事实 | C4: 附件《账户交接》载明；9/8周二、9/9周三均为交易日 | D4: —
A5: 14:30买一价为卖出测算价 | B5: 合理推断 | C5: 附件：以买一价测算，无实时接口 | D5: 成交价/可卖数需盘前复核
A6: 费用按成交额0.08%/0.03%、最低5元 | B6: 已确认事实 | C6: 附件费率表；卖0股不收 | D6: 实际佣金/印花税以账单为准
A7: 今日新购电池4,000股T+1不可卖 | B7: 已确认事实 | C7: 附件当日成交记录 | D7: 9/9解锁后可卖
A8: 联动情景：NE-25%/公用-8%/ETF-12% | B8: 已确认事实 | C8: 附件风险预算 | D8: —
A9: 次日新能源-5%为敏感性情景 | B9: 用户指定 | C9: 题面要求 | D9: 以实际开盘价重算
A10: 缺少实时盘口/涨跌停状态 | B10: 仍缺证据 | C10: 附件：成交前须复核 | D10: 实际成交后按真实价与费用重算权重与损失率
A11: 无其他账户资产、无负债 | B11: 已确认事实 | C11: 附件：无负债/融资/质押 | D11: —
