Workbook

Sheet 调整与情景测算
A1: 调整与情景测算（浅黄=输入区，来自交接资料；其余为公式，改输入即自动重算）
A4: 【输入区】项目 | B4: 数值 | C4: 说明
A5: 现价_光伏 | B5: 25 | C5: 元/股 14:30买一价
A6: 现价_电池 | B6: 30 | C6: 元/股 14:30买一价
A7: 现价_公用事业 | B7: 10 | C7: 元/股 14:30买一价
A8: 现价_宽基ETF | B8: 3 | C8: 元/份 14:30买一价
A9: 数量_光伏 | B9: 20000 | C9: 股
A10: 数量_电池_旧批 | B10: 16000 | C10: 股 今日可卖
A11: 数量_电池_新批 | B11: 4000 | C11: 股 10:12买入今日不可卖
A12: 数量_公用事业 | B12: 30000 | C12: 股
A13: 数量_宽基ETF | B13: 120000 | C13: 份
A14: 成本_光伏 | B14: 600000 | C14: 元
A15: 成本_电池_旧批 | B15: 560000 | C15: 元
A16: 成本_电池_新批 | B16: 122000 | C16: 元 已从现金扣除
... A30: 上限_损失率 | B30: 0.12 | C30: 净资产比例
A32: 【各方案】交易后剩余持仓（浅黄可改；卖出=总量-剩余）
A33: 品种 | B33: 未调整 | C33: 方案A 只卖盈利公用 | D33: 方案A2 卖全部盈利品种 | E33: 方案B 按风险减仓
A34: 光伏(股) | B34: 20000 | C34: 20000 | D34: 20000 | E34: 7600
A35: 电池合计(股) | B35: 20000 | C35: 20000 | D35: 20000 | E35: 16500
A36: 公用事业(股) | B36: 30000 | C36: 0 | D36: 0 | E36: 30000
A37: 宽基ETF(份) | B37: 120000 | C37: 120000 | D37: 0 | E37: 120000
A38: 光伏 卖出(股) | B38: =$B$9-B34 | C38: =$B$9-C34 | D38: =$B$9-D34 | E38: =$B$9-E34
A39: 电池旧批 卖出(股) | B39: =($B$10+$B$11)-B35 | C39: =($B$10+$B$11)-C35 | D39: =($B$10+$B$11)-D35 | E39: =($B$10+$B$11)-E35
A40: 公用 卖出(股) | B40: =$B$12-B36 | C40: =$B$12-C36 | D40: =$B$12-D36 | E40: =$B$12-E36
A41: 宽基ETF 卖出(份) | B41: =$B$13-B37 | C41: =$B$13-C37 | D41: =$B$13-D37 | E41: =$B$13-E37
A42: 光伏 成交额 | B42: =B38*$B$5 | C42: =C38*$B$5 | D42: =D38*$B$5 | E42: =E38*$B$5
A43: 电池 成交额 | B43: =B39*$B$6 | C43: =C39*$B$6 | D43: =D39*$B$6 | E43: =E39*$B$6
A44: 公用 成交额 | B44: =B40*$B$7 | C44: =C40*$B$7 | D44: =D40*$B$7 | E44: =E40*$B$7
A45: ETF 成交额 | B45: =B41*$B$8 | C45: =C41*$B$8 | D45: =D41*$B$8 | E45: =E41*$B$8
A46: 股票费用(逐品种max5) | B46: =IF(B42>0,MAX($B$22,$B$20*B42),0)+IF(B43>0,MAX($B$22,$B$20*B43),0)+IF(B44>0,MAX($B$22,$B$20*B44),0) | C46: =IF(C42>0,MAX($B$22,$B$20*C42),0)+IF(C43>0,MAX($B$22,$B$20*C43),0)+IF(C44>0,MAX($B$22,$B$20*C44),0) | D46: =IF(D42>0,MAX($B$22,$B$20*D42),0)+IF(D43>0,MAX($B$22,$B$20*D43),0)+IF(D44>0,MAX($B$22,$B$20*D44),0) | E46: =IF(E42>0,MAX($B$22,$B$20*E42),0)+IF(E43>0,MAX($B$22,$B$20*E43),0)+IF(E44>0,MAX($B$22,$B$20*E44),0)
A47: ETF费用 | B47: =IF(B45>0,MAX($B$22,$B$21*B45),0) | C47: =IF(C45>0,MAX($B$22,$B$21*C45),0) | D47: =IF(D45>0,MAX($B$22,$B$21*D45),0) | E47: =IF(E45>0,MAX($B$22,$B$21*E45),0)
A48: 费用合计 | B48: =B46+B47 | C48: =C46+C47 | D48: =D46+D47 | E48: =E46+E47
A49: 成交后现金 | B49: =$B$19+B42+B43+B44+B45-B48 | C49: =$B$19+C42+C43+C44+C45-C48 | D49: =$B$19+D42+D43+D44+D45-D48 | E49: =$B$19+E42+E43+E44+E45-E48
A50: 剩余光伏市值 | B50: =B34*$B$5 | C50: =C34*$B$5 | D50: =D34*$B$5 | E50: =E34*$B$5
A51: 剩余电池市值 | B51: =B35*$B$6 | C51: =C35*$B$6 | D51: =D35*$B$6 | E51: =E35*$B$6
A52: 剩余公用市值 | B52: =B36*$B$7 | C52: =C36*$B$7 | D52: =D36*$B$7 | E52: =E36*$B$7
A53: 剩余ETF市值 | B53: =B37*$B$8 | C53: =C37*$B$8 | D53: =D37*$B$8 | E53: =E37*$B$8
A54: 成交后净资产 D | B54: =B49+B50+B51+B52+B53 | C54: =C49+C50+C51+C52+C53 | D54: =D49+D50+D51+D52+D53 | E54: =E49+E50+E51+E52+E53
A55: 光伏 权重 | B55: =B50/B54 | C55: =C50/C54 | D55: =D50/D54 | E55: =E50/E54
A56: 电池 权重 | B56: =B51/B54 | C56: =C51/C54 | D56: =D51/D54 | E56: =E51/E54
...

Sheet 账户核对
A1: 账户核对：13:00汇总页 与 14:30持仓 勾稽（采用口径=14:30）
A3: 品种(批次) | B3: 数量 | C3: 13:00价 | D3: 13:00市值 | E3: 14:30价 | F3: 14:30市值 | G3: 差额 | H3: 批次成本 | I3: 浮动盈亏
A4: 光伏设备 EQ01 | B4: 20000 | C4: 26 | D4: =B4*C4 | E4: 25 | F4: =B4*E4 | G4: =F4-D4 | H4: 600000 | I4: =F4-H4
A5: 电池制造 EQ02(旧16000+新4000) | B5: 20000 | C5: 31 | D5: =B5*C5 | E5: 30 | F5: =B5*E5 | G5: =F5-D5 | H5: 682000 | I5: =F5-H5
A6: 公用事业 EQ03 | B6: 30000 | C6: 10 | D6: =B6*C6 | E6: 10 | F6: =B6*E6 | G6: =F6-D6 | H6: 240000 | I6: =F6-H6
A7: 宽基ETF ETF01 | B7: 120000 | C7: 3 | D7: =B7*C7 | E7: 3 | F7: =B7*E7 | G7: =F7-D7 | H7: 336000 | I7: =F7-H7
A8: 证券市值合计 | D8: =SUM(D4:D7) | F8: =SUM(F4:F7) | G8: =F8-D8
A9: 现金 | F9: ='调整与情景测算'!$B$19
A10: 账户净资产 | D10: =D8+F9 | F10: =F8+F9 | G10: =F10-D10
A12: 【勾稽结论】
A13: 13:00汇总页净资产=2,030,000元（用13:00价：光伏26、电池31）；14:30重新按买一价估值=1,990,000元。
A14: 差额=40,000元，全部来自价格变动：光伏26→25（20,000股，-20,000）+电池31→30（20,000股，-20,000）；公用、ETF价格未变。
A15: 现金两时点均为230,000元；10:12买入电池4,000股、总成本122,000元已在现金中扣过，本方案不再重复扣现金。
A16: 采用口径：净资产1,990,000元、现金230,000元（14:30）。无负债、无融资、无其他资产。
A18: 【可卖批次台账】
A19: 品种 | B19: 总数量 | C19: 今日可卖 | D19: 不可卖原因
A20: 光伏设备 | B20: 20000 | C20: 20000 | D20: —
A21: 电池制造-旧批 | B21: 16000 | C21: 16000 | D21: —
A22: 电池制造-新批 | B22: 4000 | C22: 0 | D22: 今日买入，下一交易日方可卖
A23: 公用事业 | B23: 30000 | C23: 30000 | D23: —
A24: 宽基ETF | B24: 120000 | C24: 120000 | D24: —
A25: 合计 | B25: 190000 | C25: 186000
A26: 【未调整现状：四项硬约束】
A27: 指标 | B27: 现状值 | C27: 判定
A28: 现金 | B28: ='调整与情景测算'!$B$49 | C28: ='调整与情景测算'!$B$68
A29: 光伏权重 | B29: ='调整与情景测算'!$B$55 | C29: ='调整与情景测算'!$B$69
A30: 电池权重 | B30: ='调整与情景测算'!$B$56 | C30: ='调整与情景测算'!$B$70
A31: 新能源权重 | B31: ='调整与情景测算'!$B$59 | C31: ='调整与情景测算'!$B$71
A32: 联动损失率 | B32: ='调整与情景测算'!$B$67 | C32: ='调整与情景测算'!$B$72

Sheet 客户沟通说明
A1: 致客户：集中持仓处理方案说明（可直接使用）
A3: 一、我们核对了账户
A4: 13:00汇总页显示净资产203.0万元，14:30按最新买一价重估为199.0万元。差额4.0万元全部是行情波动（光伏、电池各跌约1元/股），不是现金少了；现金仍为23.0万元。上午10:12补买的电池4,000股（成本12.2万元）已经从现金里扣过，不会再扣一次。
A6: 二、为什么不能“只卖赚钱的公用事业、留下亏损电池等反弹”
A7: 您的想法是只卖出盈利的公用事业、保留亏损的电池和光伏。我们按四项风控硬指标测算了这个做法：卖完全部公用事业后，现金充足（约53.0万元，达标），但光伏仍占约25.1%、电池约30.2%、光伏+电池合计约55.3%，联动冲击损失率约16.0%。即使把同样盈利的宽基ETF也一并卖掉，新能源占比仍约55.3%、损失率仍约13.8%。原因是：亏损集中在光伏、电池，而这两项在联动情景里恰恰是各跌25%的最大风险来源；卖掉跌得少（公用事业跌8%、ETF跌12%）的盈利品种，并不能把真正的风险降下来。
A9: 三、推荐做法（按组合风险减仓）
A10: 在不增资、不加杠杆、且今天不新买入的前提下，建议：
A11: · 卖出光伏12,400股（保留7,600股）；
A12: · 卖出电池旧批次3,500股（保留电池共16,500股，其中今天新买入的4,000股一股不动）；
A13: · 公用事业、宽基ETF全部保留。
A14: 成交后：现金约64.5万元，净资产约198.97万元；电池占比约24.9%、光伏+电池合计约34.4%、联动损失率约11.98%。四项指标同时回到限制以内。本次减仓实现的是账面亏损约7.98万元（光伏约-6.22万、电池约-1.76万，已扣费），这是把过度集中的风险换回来的代价；剩余持仓继续保留，并非清仓离场。
A16: 四、如果您坚持一股电池都不卖
... A25: 本测算用的是14:30买一价，不是实时成交价；实际以成交时买一价、整手（100股）、最低佣金和盘口为准。我们不代您下单、不承诺回本或反弹。请确认：是否按推荐数量执行；若坚持全留电池，请明确是否放宽单票上限或追加资金。

Sheet 规则与自检
A1: 交易日历、if→then 规则与交付自检
A3: ① 交易日历（按常规工作日，遇节假日顺延到下一交易日）
A4: 日期 | B4: 星期 | C4: 是否交易日 | D4: 时段/动作 | E4: 资金可用 | F4: 备注
A5: 2026-09-08 | B5: 周二 | C5: 是 | D5: 14:30后至收盘前按条件挂单 | E5: T+1可用 | F5: 测算基准日；今日新批电池4000股不可卖
A6: 2026-09-09 | B6: 周三 | C6: 是 | D6: 开盘前重核可卖数与报价 | E6: — | F6: 下一交易日；若9/8成交，电池新批4000股转入可卖（本方案不动用）
A8: ② 硬约束反解与判定（当前=未调整列B；PlanB=E列）
A9: 约束 | B9: 阈值 | C9: 当前值 | D9: 反解达标所需 | E9: PlanB值 | F9: 判定
A10: 现金 | B10: ≥300,000 | C10: ='调整与情景测算'!$B$49 | D10: 卖出约8,000股光伏即够 | E10: ='调整与情景测算'!$E$49 | F10: ='调整与情景测算'!$E$68
A11: 光伏权重 | B11: ≤25% | C11: ='调整与情景测算'!$B$55 | D11: 光伏≤约19,900股 | E11: ='调整与情景测算'!$E$55 | F11: ='调整与情景测算'!$E$69
A12: 电池权重 | B12: ≤25% | C12: ='调整与情景测算'!$B$56 | D12: 电池≤约16,500股(卖旧批3,500) | E12: ='调整与情景测算'!$E$56 | F12: ='调整与情景测算'!$E$70
A13: 新能源权重 | B13: ≤45% | C13: ='调整与情景测算'!$B$59 | D13: 光伏+电池市值≤约895,500 | E13: ='调整与情景测算'!$E$59 | F13: ='调整与情景测算'!$E$71
A14: 联动损失率 | B14: ≤12% | C14: ='调整与情景测算'!$B$67 | D14: 组合后损失≤约238,760 | E14: ='调整与情景测算'!$E$67 | F14: ='调整与情景测算'!$E$72
A16: ③ if→then 交易纪律（今日=9/8，次日=9/9；数量口径=累计总卖出量，基准=今日可卖量）
A17: 规则号 | B17: 触发条件(阈值+时点) | C17: 方向自检 | D17: 动作 | E17: 数量/口径 | F17: 执行时点 | G17: 未成交后手/复核
A18: R1 | B18: 买一价正常、可卖数已确认，且收盘前 | C18: 卖出盈利品种不能降新能源风险，必须减光伏/电池才有效 | D18: 限价卖光伏12,400股、电池旧批3,500股 | E18: 光伏12,400+电池3,500(累计) | F18: 9/8收盘前 | G18: 成交后复核E列四指标；未成交部分转R2
A19: R2 | B19: 上述任一品种只部分成交 | C19: 成交才算减仓，未成交不算 | D19: 按实际成交价重算权重与损失率 | E19: 按实际成交(累计) | F19: 9/8收盘后 | G19: 缺口在9/9开盘后按R4补足
A20: R3 | B20: 光伏或电池跌停/无买盘 | C20: 强行市价会放大滑点，不追 | D20: 当日不成交该品种，维持未达标 | E20: 0(未成交) | F20: 9/8 | G20: 次日开盘重核；不得改卖公用/ETF凑数
A21: R4 | B21: 9/9开盘前 | C21: 报价与可卖数以开盘为准 | D21: 重核可卖数与最新价，按剩余持仓重算四指标 | E21: — | F21: 9/9开盘 | G21: 电池新批4,000股转可卖但本方案不动用
A22: R5 | B22: 盘中光伏+电池累计再跌约5% | C22: 下跌使权重/损失率恶化(分母变小) | D22: 重算损失率；当前余量仅约0.24个百分点 | E22: 一旦>12%或电池>25%即再减新能源 | F22: 9/9盘中 | G22: 禁止补仓摊薄；按下行档位再减
A23: R6 | B23: 成交价低于假设致现金<30万 | C23: 现金是硬下限 | D23: 优先补卖光伏(不碰电池新批) | E23: 补卖至现金≥30万 | F23: 成交后即时 | G23: 复核现金≥30万且单票≤25%
A26: ④ 交付自检回执（填值，非打勾）
A27: 自检项 | B27: 填写值
A28: 交付清单 | B28: 3张工作表：账户核对 / 调整与情景测算 / 客户沟通说明(+规则与自检)；单一xlsx文件
A29: 占比分母 | B29: 权重分母=成交后净资产D；PlanB D=1,989,668(=1,990,000-费用332)
A30: 权重加总 | B30: 账户核对/测算row61=100.00%（已加总校验）
A31: 最紧约束 | B31: 联动损失率：PlanB 11.98% vs 12%阈值；反解=光伏卖12,400+电池旧批卖3,500；规则R1
A32: 相邻一手 | B32: 光伏少卖100→损失率12.02%超线；电池少卖100→电池权重25.03%超线（故数量不可再少）
A33: 最不利情景 | B33: 次日新能源再跌5%后：损失率11.76%，仍≤12%；余量极小，R5触发
A34: 费用口径 | B34: 股票0.08%最低5、ETF0.03%最低5；PlanB费用332元；隐含费率332/415,000=0.080%
A35: 跨文件一致 | B35: 现金644,668 / 电池权重24.88% / 损失率11.98% 在测算E列与客户说明一致
A36: 可复算性 | B36: 改测算sheet浅黄输入区，全表公式自动重算；已用LibreOffice重算无#REF/#VALUE错误
A37: 非执行声明 | B37: 仅条件测算，不代下单、不承诺回本；成交价以实盘为准
