Workbook

Sheet 账户核对
A1: 砻淬资本 — 集中持仓复核：账户核对
A2: 基准日：2026年9月8日（周二）14:30 买一价 | 人民币普通证券账户 | 无负债/融资/质押
A4: 一、输入参数（蓝色底为录入值，其余为公式自动计算）
A5: 代号 | B5: 资产 | C5: 数量(股/份) | D5: 批次总成本(元) | E5: 今日可卖 | F5: 13:00价 | G5: 14:30买一价 | H5: 备注
A6: EQ01 | B6: 光伏设备 | C6: 20000 | D6: 600000 | E6: 20000 | F6: 26 | G6: 25
A7: EQ02 | B7: 电池制造（旧批次） | C7: 16000 | D7: 560000 | E7: 16000 | F7: 31 | G7: 30 | H7: 历史持仓，今日可卖
A8: EQ02 | B8: 电池制造（今日买入） | C8: 4000 | D8: 122000 | E8: 0 | F8: 31 | G8: 30 | H8: 9/8 10:12买入，T+1当日不可卖
A9: EQ03 | B9: 公用事业 | C9: 30000 | D9: 240000 | E9: 30000 | F9: 10 | G9: 10
A10: ETF01 | B10: A股宽基ETF | C10: 120000 | D10: 336000 | E10: 120000 | F10: 3 | G10: 3
A12: 期初现金 | D12: 230000
A13: 股票卖出费率 | D13: 0.0008
A14: ETF卖出费率 | D14: 0.0003
A15: 每笔最低佣金(元) | D15: 5
A17: 二、13:00 汇总页勾稽
A18: 项目 | B18: 数量 | C18: 13:00价 | D18: 市值(元) | E18: 汇总页总资产 | F18: 差异(元)
A19: =A6&" "&B6 | B19: =C6 | C19: =F6 | D19: =B19*C19
A20: =A7&" "&B7 | B20: =C7 | C20: =F7 | D20: =B20*C20
A21: =A8&" "&B8 | B21: =C8 | C21: =F8 | D21: =B21*C21
A22: =A9&" "&B9 | B22: =C9 | C22: =F9 | D22: =B22*C22
A23: =A10&" "&B10 | B23: =C10 | C23: =F10 | D23: =B23*C23
A24: 证券市值合计 | D24: =SUM(D19:D23)
A25: 现金 | D25: ='账户核对'!D12
A26: 总资产（计算值） | D26: =D24+D25 | E26: 2030000 | F26: =D26-E26
A28: 三、14:30 买一价勾稽与浮动盈亏
A29: 项目 | B29: 数量 | C29: 14:30价 | D29: 市值(元) | E29: 成本(元) | F29: 浮动盈亏(元) | G29: 盈亏率
A30: =A6&" "&B6 | B30: =C6 | C30: =G6 | D30: =B30*C30 | E30: =D6 | F30: =D30-E30 | G30: =F30/E30
A31: =A7&" "&B7 | B31: =C7 | C31: =G7 | D31: =B31*C31 | E31: =D7 | F31: =D31-E31 | G31: =F31/E31
A32: =A8&" "&B8 | B32: =C8 | C32: =G8 | D32: =B32*C32 | E32: =D8 | F32: =D32-E32 | G32: =F32/E32
A33: =A9&" "&B9 | B33: =C9 | C33: =G9 | D33: =B33*C33 | E33: =D9 | F33: =D33-E33 | G33: =F33/E33
A34: =A10&" "&B10 | B34: =C10 | C34: =G10 | D34: =B34*C34 | E34: =D10 | F34: =D34-E34 | G34: =F34/E34
A35: 电池合计（旧+新） | D35: =D31+D32 | E35: =E31+E32 | F35: =D35-E35 | G35: =F35/E35
A36: 证券市值合计 | D36: =SUM(D30:D34)
A37: 现金 | D37: ='账户核对'!D12
A38: 净资产（14:30，未调整） | D38: =D36+D37
A40: 四、13:00→14:30 净资产变动来源
A41: 项目 | B41: 价差 | C41: 数量 | D41: 贡献(元)
A42: =B6 | B42: =G6-F6 | C42: =C6 | D42: =B42*C42
A43: =B7 | B43: =G7-F7 | C43: =C7 | D43: =B43*C43
A44: =B8 | B44: =G8-F8 | C44: =C8 | D44: =B44*C44
A45: =B9 | B45: =G9-F9 | C45: =C9 | D45: =B45*C45
...

Sheet 调整与情景测算
A1: 调整与情景测算
A2: 价格引用'账户核对'表14:30买一价；蓝色格为可修改卖出数量，其余自动计算。费用每品种每日合并一笔，最低5元。
A4: 一、卖出数量与成交额
A5: 项目 | B5: 未调整 | C5: 方案A:只卖盈利 | D5: 方案B:风险减仓
A6: 卖出光伏(股) | B6: 0 | C6: 0 | D6: 4000
A7: 卖出电池旧批次(股) | B7: 0 | C7: 0 | D7: 3500
A8: 卖出电池今日买入(股) | B8: 0 | C8: 0 | D8: 0
A9: 卖出公用事业(股) | B9: 0 | C9: 30000 | D9: 11300
A10: 卖出ETF(份) | B10: 0 | C10: 120000 | D10: 120000
A11: 光伏成交额(元) | B11: 0 | C11: =C6*'账户核对'!G6 | D11: =D6*'账户核对'!G6
A12: 电池成交额(元) | B12: 0 | C12: =C7*'账户核对'!G7 | D12: =D7*'账户核对'!G7
A13: 公用成交额(元) | B13: 0 | C13: =C9*'账户核对'!G9 | D13: =D9*'账户核对'!G9
A14: ETF成交额(元) | B14: 0 | C14: =C10*'账户核对'!G10 | D14: =D10*'账户核对'!G10
A15: 光伏费用(元) | B15: 0 | C15: =IF(C11>0,MAX(C11*'账户核对'!D13,'账户核对'!D15),0) | D15: =IF(D11>0,MAX(D11*'账户核对'!D13,'账户核对'!D15),0)
A16: 电池费用(元) | B16: 0 | C16: =IF(C12>0,MAX(C12*'账户核对'!D13,'账户核对'!D15),0) | D16: =IF(D12>0,MAX(D12*'账户核对'!D13,'账户核对'!D15),0)
A17: 公用费用(元) | B17: 0 | C17: =IF(C13>0,MAX(C13*'账户核对'!D13,'账户核对'!D15),0) | D17: =IF(D13>0,MAX(D13*'账户核对'!D13,'账户核对'!D15),0)
A18: ETF费用(元) | B18: 0 | C18: =IF(C14>0,MAX(C14*'账户核对'!D14,'账户核对'!D15),0) | D18: =IF(D14>0,MAX(D14*'账户核对'!D14,'账户核对'!D15),0)
A19: 费用合计(元) | B19: 0 | C19: =SUM(C15:C18) | D19: =SUM(D15:D18)
A20: 净回笼(元) | B20: 0 | C20: =C11+C12+C13+C14-C19 | D20: =D11+D12+D13+D14-D19
A22: 二、交易后剩余持仓与现金
A23: 项目 | B23: 未调整 | C23: 方案A | D23: 方案B
A24: 光伏剩余市值(元) | B24: ='账户核对'!C6*'账户核对'!G6 | C24: =('账户核对'!C6-C6)*'账户核对'!G6 | D24: =('账户核对'!C6-D6)*'账户核对'!G6
A25: 电池剩余市值(元) | B25: =('账户核对'!C7+'账户核对'!C8)*'账户核对'!G7 | C25: =('账户核对'!C7-C7+'账户核对'!C8-C8)*'账户核对'!G7 | D25: =('账户核对'!C7-D7+'账户核对'!C8-D8)*'账户核对'!G7
A26: 公用剩余市值(元) | B26: ='账户核对'!C9*'账户核对'!G9 | C26: =('账户核对'!C9-C9)*'账户核对'!G9 | D26: =('账户核对'!C9-D9)*'账户核对'!G9
A27: ETF剩余市值(元) | B27: ='账户核对'!C10*'账户核对'!G10 | C27: =('账户核对'!C10-C10)*'账户核对'!G10 | D27: =('账户核对'!C10-D10)*'账户核对'!G10
A28: 交易后现金(元) | B28: ='账户核对'!D12 | C28: ='账户核对'!D12+C20 | D28: ='账户核对'!D12+D20
A29: 交易后净资产(元) | B29: =B24+B25+B26+B27+B28 | C29: =C24+C25+C26+C27+C28 | D29: =D24+D25+D26+D27+D28
A31: 三、交易后权重
A32: 项目 | B32: 未调整 | C32: 方案A | D32: 方案B
A33: 光伏权重 | B33: =B24/B29 | C33: =C24/C29 | D33: =D24/D29
A34: 电池权重 | B34: =B25/B29 | C34: =C25/C29 | D34: =D25/D29
A35: 新能源合计权重 | B35: =B33+B34 | C35: =C33+C34 | D35: =D33+D34
A36: 公用权重 | B36: =B26/B29 | C36: =C26/C29 | D36: =D26/D29
A37: ETF权重 | B37: =B27/B29 | C37: =C27/C29 | D37: =D27/D29
A38: 现金权重 | B38: =B28/B29 | C38: =C28/C29 | D38: =D28/D29
A39: 权重合计 | B39: =B33+B34+B36+B37+B38 | C39: =C33+C34+C36+C37+C38 | D39: =D33+D34+D36+D37+D38
A41: 四、联动情景损失（光伏/电池-25%，公用-8%，ETF-12%，现金不变）
A42: 项目 | B42: 未调整 | C42: 方案A | D42: 方案B
A43: 光伏冲击损失(元) | B43: =B24*0.25 | C43: =C24*0.25 | D43: =D24*0.25
A44: 电池冲击损失(元) | B44: =B25*0.25 | C44: =C25*0.25 | D44: =D25*0.25
...

Sheet 客户沟通说明
A1: 客户沟通说明（可直接使用）
A2: 以下文字供投资经理与客户收盘沟通时使用，数据以14:30买一价测算，成交前需复核盘口。
A4: 一、账户现状（9月8日14:30）
A5: 账户净资产199.0万元，较13:00汇总页203.0万元减少4.0万元，全部来自光伏和电池的价格下跌（光伏26→25元、电池31→30元），无现金流出。现金23.0万元，低于30.0万元的内部下限。 持仓浮动盈亏：光伏-10.0万元、电池-8.2万元（含今日上午补仓的4000股-0.2万元）、公用事业+6.0万元、宽基ETF+2.4万元。 四项内部约束当前全部不达标：单票光伏占比25.1%、单票电池占比30.2%、新能源合计55.3%、联动情景损失率17.2%。现金缺口7.0万元。
A6: 二、为什么不能只卖赚钱的公用事业
A7: 您提出只卖掉盈利的公用事业股票、保留亏损的电池股等反弹，我们理解这个想法，但按风控口径测算后不可行： 如果把公用事业和宽基ETF全部卖出（合计回笼约65.9万元，费用538元），现金会升至88.9万元，现金约束达标。但光伏和电池一股不卖，单票电池仍占30.2%、新能源合计仍占55.3%、联动情景损失率13.8%——三项核心约束仍然超限。 原因是：联动情景假设光伏和电池同时下跌25%，这部分损失不因为卖出盈利品种而减少。卖公用事业只能回笼现金，无法降低新能源敞口在极端情景下的损失。换句话说，'只卖赚钱的'解决了现金问题，但没有解决集中度和尾部风险问题。
A8: 三、建议方案：按组合风险减仓
A9: 在不增加外部资金、不加杠杆的前提下，我们建议今天收盘前执行以下操作（均为100股整数倍）： 1. 卖出光伏4000股（成交价25元，回笼约10.0万元）——这是目前唯一同时拉低单票权重和联动损失的品种； 2. 卖出电池旧批次3500股（成交价30元，回笼约10.5万元）——今日上午补仓的4000股按T+1规则今天不可卖，明天才能卖； 3. 卖出公用事业11300股（成交价10元，回笼约11.3万元）——保留18700股； 4. 卖出宽基ETF全部120000份（成交价3元，回笼约36.0万元）。 四项合计成交额约67.7万元，费用约362元。交易后： • 净资产约198.9万元； • 现金约90.7万元（远超30万元下限）； • 光伏权重20.1%、电池权重24.9%、新能源合计45.0%、联动损失率12.0%——四项约束全部达标。 已实现盈亏合计约+0.87万元（公用事业和ETF的盈利覆盖光伏和电池的小额亏损后仍为正），没有把账面亏损'割肉'在最低点——光伏保留80%、电池保留约75%（旧批次）。
A10: 四、关于保留电池股
A11: 我们注意到您希望保留新能源方向一年。方案保留了电池旧批次12500股和今日新补的4000股，合计16500股（市值约49.5万元），不是清仓。卖3500股旧批次的目的是把单票电池权重从30.2%压到25%以内，这是硬约束。 如果您坚持一股电池都不卖，我们必须如实说明：即使卖掉全部光伏、公用和ETF，电池权重仍为30.2%，单票25%的约束无法通过卖出其他品种满足。要做到这一点，需要约41万元的外部资金追加进来，或者由风控审批把单票上限从25%放宽到约30.2%。我们不替您默许提高风险预算，这两条路需要您和风控共同决定。
A12: 五、明天（9月9日）怎么安排
A13: 1. 今日新买入的电池4000股明天可卖，开盘前先核对可卖数量和实时报价； 2. 如果明天新能源再跌5%（在今天调整后的基础上），我们按新分母重算：联动损失率约11.7%，各权重仍在限内，不需要追加卖出； 3. 如果明天新能源反弹导致电池权重回到25%以上，我们会卖出电池旧批次把权重压回24.9%； 4. 如果今天任何一笔单子未成交或跌停，我们不强卖，未成交部分顺延到明天开盘处理，跌停解除前不做任何加仓； 5. 在所有约束回到限内之前，我们不会加仓、回补或做T新能源。
... A17: 附：关键数字速览
A18: 指标 | B18: 未调整 | C18: 方案A(只卖盈利) | D18: 方案B(风险减仓)
A19: 净资产(万元) | B19: 199.0 | C19: 198.9 | D19: 198.9
A20: 现金(万元) | B20: 23.0 | C20: 88.9 | D20: 90.7
A21: 光伏权重 | B21: 25.1% | C21: 25.1% | D21: 20.1%
A22: 电池权重 | B22: 30.2% | C22: 30.2% | D22: 24.9%
A23: 新能源合计 | B23: 55.3% | C23: 55.3% | D23: 45.0%
A24: 联动损失率 | B24: 17.2% | C24: 13.8% | D24: 12.0%
A25: 四项约束 | B25: 全部不达标 | C25: 仅现金达标 | D25: 全部达标
